<?xml version="1.0" ?>

<robot name="ruka_gz">

    <material name="grey">
        <color rgba="0.4 0.4 0.4 1"/>
    </material>

    <material name="red">
        <color rgba="1 0 0 1"/>
    </material>
<!-- 
    <link name="world"/>

    <joint name="ruka_joint_world" type="fixed">
        <parent link="world"/>
        <child link="base_link"/>
        <origin rpy="0 0 0" xyz="0 0 0"/>
    </joint> -->

    <link name="base_link">

        <visual>
            <origin rpy="0 0 0" xyz="0 0 0"/>
            <geometry>
                <mesh filename="file://$(find ruka)/config/dae/base.dae"/>
            </geometry>
            <material name="grey"/>
        </visual>

        <collision>
            <origin rpy="0 0 0" xyz="0 0 0"/>
            <geometry>
                <mesh filename="file://$(find ruka)/config/mesh/base.stl"/>
            </geometry>
        </collision>
 
    </link>

    <joint name="base_link__link_01" type="revolute">
        <axis xyz="0 0 1"/>

        <!-- <safety_controller k_position="100.0" k_velocity="40.0" soft_lower_limit="-2.908" soft_upper_limit="2.908" /> -->

        <limit effort="1000.0" lower="-2.96" upper="2.96" velocity="0.5"/>
        <origin rpy="0 0 0" xyz="0 0 0.03"/>
        <parent link="base_link"/>
        <child link="link_01"/>
        
    </joint>

    <link name="link_01">

        <visual>
            <origin rpy="0 0 0" xyz="0 0 0.032"/>
            <geometry>
                <mesh filename="file://$(find ruka)/config/dae/j1.dae"/>
            </geometry>
            <material name="grey"/>
        </visual>

        <collision>
             <origin rpy="0 0 0" xyz="0 0 0.032"/>
            <geometry>
                <mesh filename="file://$(find ruka)/config/mesh/j1.stl"/>
            </geometry>
        </collision> 
 
    </link>


    <joint name="link_01__link_01_red" type="fixed">
        <origin rpy="0 0 0" xyz="0 0 0.032"/>
        <parent link="link_01"/>
        <child link="link_01_red"/>
    </joint>

    <link name="link_01_red">

        <visual>
            <origin rpy="-1.57 1.57 0" xyz="0.010 0.074 0.147"/>
            <geometry>
                <mesh filename="file://$(find ruka)/config/mesh/j1_covers.stl"/>
            </geometry>
            <material name="red"/>
        </visual>

        <collision>
            <origin rpy="-1.57 1.57 0" xyz="0.010 0.074 0.147"/>
            <geometry>
                <mesh filename="file://$(find ruka)/config/dae/j1_covers.dae"/>
            </geometry>
           
        </collision>

        <visual>
            <origin rpy="-1.57 1.57 3.14" xyz="0.010 -0.074 0.147"/>
            <geometry>
                <mesh filename="file://$(find ruka)/config/mesh/j1_covers1.stl"/>
            </geometry>
            <material name="red"/>
        </visual>

        <collision>
            <origin rpy="-1.57 1.57 3.14" xyz="0.010 -0.074 0.147"/>
            <geometry>
                <mesh filename="file://$(find ruka)/config/dae/j1_covers1.dae"/>
            </geometry>
        </collision>

        <visual>
            <origin rpy="0 0 0" xyz="-0.115 0 0.106"/>
            <geometry>
                <mesh filename="file://$(find ruka)/config/mesh/j1backcover.stl"/>
            </geometry>
            <material name="red"/>
        </visual>

        <collision>
            <origin rpy="0 0 0" xyz="-0.115 0 0.106"/>
            <geometry>
                <mesh filename="file://$(find ruka)/config/dae/j1backcover.dae"/>
            </geometry>
         
        </collision>


    </link>




    <joint name="link_01__link_02" type="revolute">
        <axis xyz="0 0 1"/>

        <!-- <safety_controller k_position="100.0" k_velocity="40.0" soft_lower_limit="-3.518" soft_upper_limit="-0.052" /> -->

        <limit effort="1000.0" lower="-3.57" upper="0" velocity="0.5"/>
        <origin rpy="1.57 -1.57 0" xyz="0.01 0 0.179"/>   <!-- origin rpy="1.57 0 0"-->
        <parent link="link_01"/>
    
        <child link="link_02"/>
    </joint> 

    <link name="link_02">
        <inertial>
            <mass value="2.74"/>
            <origin rpy="0 0 0" xyz="0 -0.06861 0.0322285"/>
            <inertia ixx="0.0182856182281" ixy="0.0" ixz="0.0" iyy="0.00621358421175" iyz="-0.00472844221905" izz="0.0161514346309"/>
        </inertial>


        <visual>
            <origin rpy="0 0 1.57" xyz="0 0 0"/>
            <geometry>
                <mesh filename="file://$(find ruka)/config/mesh/j2.stl"/>
            </geometry>
            <material name="grey"/>
        </visual>

        <collision>
            <origin rpy="0 0 1.57" xyz="0 0 0"/>
            <geometry>
                <mesh filename="file://$(find ruka)/config/dae/j2.dae"/>
            </geometry>
        
        </collision>

       

    </link>




    <joint name="link_02__link_02_red" type="fixed">
        <origin rpy="0 0 0" xyz="0 0 0"/>
        <parent link="link_02"/>
        <child link="link_02_red"/>
    </joint>

    <link name="link_02_red">
        <visual>
            <origin rpy="0 0 1.57" xyz="0 0 0"/>
            <geometry>
                <mesh filename="file://$(find ruka)/config/mesh/j2cover2s.stl"/>
            </geometry>
            <material name="red"/>
        </visual>

        <collision>
            <origin rpy="0 0 1.57" xyz="0 0 0"/>
            <geometry>
                <mesh filename="file://$(find ruka)/config/dae/j2cover2s.dae"/>
            </geometry>
           
        </collision>

        <!-- <visual>
            <origin rpy="0 0 -1.57" xyz="0.280 0 0.058"/>
            <geometry>
                <mesh filename="file://$(find ruka)/config/mesh/j2cover1.stl"/>
            </geometry>
            <material name="red"/>
        </visual> -->

    </link>



   

    <joint name="link_02__link_03" type="revolute">
        <axis xyz="0 0 1"/>

        <!-- <safety_controller k_position="100.0" k_velocity="40.0" soft_lower_limit="0.067" soft_upper_limit="5.178" /> -->

        <limit effort="1000.0" lower="-0.035" upper="5.23" velocity="0.5"/>
        <origin rpy="0 0 0.04" xyz="0 0.28 0"/> 
        <!-- !!!!!!!!!!!!!!!!!!!!! /> -->
        <parent link="link_02"/>
        <child link="link_03"/>
    </joint>

    <link name="link_03">
      
        <!-- <visual>
            <origin rpy="0 0 0" xyz="0 0 0" />
            <geometry>
                <cylinder radius="0.019" length="0.104" />
            </geometry>
          
        </visual> -->

         <visual>
            <origin rpy="0 0 -1.57" xyz="0 0 0"/>
            <geometry>
                <mesh filename="file://$(find ruka)/config/mesh/j3.stl"/>
            </geometry>
            <material name="grey"/>
        </visual>


         <collision>
            <origin rpy="0 0 -1.57" xyz="0 0 0"/>
            <geometry>
                <mesh filename="file://$(find ruka)/config/dae/j3.dae"/>
            </geometry>
    
        </collision>

        <!-- <collision>
            <origin rpy="0 0 0" xyz="0 0 0" />
            <geometry>
                <cylinder radius="0.019" length="0.104" />
            </geometry>
          </collision> -->

       
    </link>

  




    <joint name="link_03__link_03_red" type="fixed">
        <origin rpy="0 0 0" xyz="0 0 0"/>
        <parent link="link_03"/>
        <child link="link_03_red"/>
    </joint>

    <link name="link_03_red">
        <visual>
            <origin rpy="0 0 -1.57" xyz="0 0 0"/>
            <geometry>
                <mesh filename="file://$(find ruka)/config/mesh/j3-cover2s.stl"/>
            </geometry>
            <material name="red"/>
        </visual>

         <collision>
            <origin rpy="0 0 -1.57" xyz="0 0 0"/>
            <geometry>
                <mesh filename="file://$(find ruka)/config/dae/j3-cover2s.dae"/>
            </geometry>
          
        </collision>

        <!-- <visual>
            <origin rpy="0 0 -1.57" xyz="0.280 0 0.058"/>
            <geometry>
                <mesh filename="file://$(find ruka)/config/mesh/j2cover1.stl"/>
            </geometry>
            <material name="red"/>
        </visual> -->

    </link>





    <joint name="link_03__link_04" type="revolute">
        <axis xyz="0 0 1"/>

        <!-- <safety_controller k_position="100.0" k_velocity="40.0" soft_lower_limit="-2.818" soft_upper_limit="2.818" /> -->

        <limit effort="1000.0" lower="-2.87" upper="2.87" velocity="0.5"/>
        <origin rpy="1.57 0 0" xyz="0.068 0 0"/>
        <parent link="link_03"/>
        <child link="link_04"/>
    </joint>

    <link name="link_04">

       
        <!-- <visual>
            <origin rpy="0 0 0" xyz="0 0 0.0455" />
            <geometry>
                <cylinder radius="0.018" length="0.091" />
            </geometry>


        </visual> -->

        <visual>
            <origin rpy="0 0 1.57" xyz="0 0 0"/>
            <geometry>
                <mesh filename="file://$(find ruka)/config/mesh/j4.stl"/>
            </geometry>
            <material name="grey"/>
        </visual>

         <collision>
            <origin rpy="0 0 1.57" xyz="0 0 0"/>
            <geometry>
                <mesh filename="file://$(find ruka)/config/dae/j4.dae"/>
            </geometry>

        </collision>


       
    </link>





    <joint name="link_04__link_04_red" type="fixed">
        <origin rpy="0 0 0" xyz="0 0 0"/>
        <parent link="link_04"/>
        <child link="link_04_red"/>
    </joint>

    <link name="link_04_red">
        <visual>
            <origin rpy="0 0 1.57" xyz="0 0 0"/>
            <geometry>
                <mesh filename="file://$(find ruka)/config/mesh/j4cover2s.stl"/>
            </geometry>
            <material name="red"/>
        </visual>

         <collision>
            <origin rpy="0 0 1.57" xyz="0 0 0"/>
            <geometry>
                <mesh filename="file://$(find ruka)/config/dae/j4cover2s.dae"/>
            </geometry>
       
        </collision>

        <!-- <visual>
            <origin rpy="0 0 -1.57" xyz="0.280 0 0.058"/>
            <geometry>
                <mesh filename="file://$(find ruka)/config/mesh/j2cover1.stl"/>
            </geometry>
            <material name="red"/>
        </visual> -->

    </link>





   
    <joint name="link_04__link_05" type="revolute">
        <axis xyz="0 0 1"/>

        <safety_controller k_position="100.0" k_velocity="40.0" soft_lower_limit="-2.388" soft_upper_limit="2.388" />

        <limit effort="1000.0" lower="-2.44" upper="2.44" velocity="0.5"/>
        <origin rpy="-1.57 0 0" xyz="0 0 0.271"/>
        <parent link="link_04"/>
        <child link="link_05"/>
    </joint>

    <link name="link_05">
       
        <!-- <visual>
            <origin rpy="0 0 0" xyz="0 0 0" />
            <geometry>
                <cylinder radius="0.0175" length="0.078" />
            </geometry>

          
        </visual> -->



         <visual>
            <origin rpy="0 3.14 1.57" xyz="0 0 0"/>
            <geometry>
                <mesh filename="file://$(find ruka)/config/mesh/j5.stl"/>
            </geometry>
            <material name="grey"/>
        </visual>

        <collision>
            <origin rpy="0 3.14 1.57" xyz="0 0 0"/>
            <geometry>
                <mesh filename="file://$(find ruka)/config/dae/j5.dae"/>
            </geometry>

        </collision>


        <!-- <collision>
            <origin rpy="0 0 0" xyz="0 0 0" />
            <geometry>
                <cylinder radius="0.0175" length="0.078" />
            </geometry>
          </collision> -->
 
    </link> 

  

    <joint name="link_05__link_06" type="revolute">
        <axis xyz="0 0 1"/>

        <safety_controller k_position="100.0" k_velocity="40.0" soft_lower_limit="-3.12" soft_upper_limit="3.12" />

        <limit effort="1000.0" lower="-3.14" upper="3.14" velocity="0.5"/>
        <origin rpy="1.57 0 0" xyz="0 -0.077 0"/>
        <parent link="link_05"/>
        <child link="link_06"/>
    </joint>

    <link name="link_06">

       
        <!-- <visual>
            <origin rpy="0 0 0" xyz="0 0 -0.0159" />
            <geometry>
                <cylinder radius="0.0095" length="0.0168" />
            </geometry>
        </visual> -->


         <visual>
            <origin rpy="0 0 0" xyz="0 0 0"/>
            <geometry>
                <mesh filename="file://$(find ruka)/config/dae/j6.dae"/>
            </geometry>
            <material name="grey"/>
        </visual>

        <collision>
            <origin rpy="0 0 0" xyz="0 0 0"/>
            <geometry>
                <mesh filename="file://$(find ruka)/config/mesh/j6.stl"/>
            </geometry>
            <material name="grey"/>

          </collision>

     
    </link>

   
    <!-- <gazebo reference="base_link">
      <material>Gazebo/#grey</material>
    </gazebo> -->
<!-- 
    <gazebo reference="link_01">
      <material>Gazebo/Orange</material>
    </gazebo>
   

    <gazebo reference="link_02">
      <material>Gazebo/Orange</material>
    </gazebo>
 
    <gazebo reference="link_03">
      <material>Gazebo/Orange</material>
    </gazebo>

    <gazebo reference="link_04">
      <material>Gazebo/Orange</material>
    </gazebo>

    <gazebo reference="link_05">
      <material>Gazebo/Orange</material>
    </gazebo>

    <gazebo reference="link_06">
      <material>Gazebo/Orange</material>
    </gazebo> 
-->
</robot>
